Workbook
Name Buildingcode: '[1]Scorecard (V2)'!$J$8:$J$9
Name Response: #REF!

Sheet Cover Page
B1: V. NOV 2024
B4: Legal Disclaimer and Notice - This Assessment Tool provided by CMHC is for general illustrative and estimation purposes only. The amounts it projects are based upon the information provided and the assumptions and estimates made by the model. CMHC does not guarantee these projections. They are not intended to provide financial or other advice on particular housing projects and they should not be relied upon in that regard. Neither CMHC nor any of its employees or advisors shall have any liability for the accuracy of the projections contained in the tool or for any damage caused by the use of the information. The use of this Assessment Tool and its results with regard to any housing project do not oblige CMHC to insure the project financing nor provide funding for the housing project under this initiative or under any other CMHC program or initiative. You are encouraged to contact your local CMHC Representative for assistance with this tool.
B16: This Assessment Tool is protected by copyright and is subject to the protection of intellectual property laws. Users are authorized to download the Assessment Tool for its use in relation to CMHC Apartment Construction Loan Program only and may not further copy, reproduce, modify or distribute the Assessment Tool without the prior written consent of CMHC.

Sheet Project Budget
B1: SUMMARY
B3: Project DCR | C3: =IF(OR(('Residential New'!I113+'Non-Residential'!H79)=0, ISERR(('Residential New'!I113+'Non-Residential'!H79))), 0, ('Residential New'!I104+'Non-Residential'!H71)/('Residential New'!I113+'Non-Residential'!H79)) -> 0 | E3: Project LTC | G3: =IF('Project Budget'!E25=0, 0, ('Residential New'!I109+'Non-Residential'!H75)/'Project Budget'!E25) -> 0
B4: Residential DCR | C4: ='Residential New'!I114 -> 0 | E4: Residential LTC | G4: ='Residential New'!I119 -> 0
B5: Non-Residential DCR | C5: ='Non-Residential'!H80 -> 0 | E5: Non-Residential LTC | G5: ='Non-Residential'!H85 -> 0
B6: Minimum Affordability Met? | C6: ='Residential New'!L37 -> No | E6: Total Loan Size | G6: ='Residential New'!I109+'Non-Residential'!H75 -> 0
B7: Social Outcome Score | C7: =Scoring!H92 -> 0 | E7: Additional Equity Required | G7: ='Residential New'!I126+'Non-Residential'!H91 -> 0
B9: Lending Flexibility Score | C9: =Scoring!H130 -> 0 | E9: =Scoring!C155 -> Tier 3 - Up to 90% LTC, 45 yrs Am, 10 yr term
B13: Total Project Budget Costs
B15: 1. Project budget | E15: Total Project Costs
B17: Land Market Value
B18: Hard costs
B19: Soft costs
B20: Financing costs
B21: HST
B22: Misc and Buffer
B23: Other (describe)
B24: Other (describe)
B25: Total Budget (Uses) | E25: =SUM(E17:E24) -> 0
B27: Other Sources of Funding
B28: Owner cash equity (Cell I127 in 'Residential New' Tab) + Cell G92 in 'Non Residential' Tab) | E28: ='Residential New'!I127+'Non-Residential'!H92 -> 0
B29: Land Value Equity (Land Market Value - Land Acquisition Cost)
B30: Other Financing (describe )
B31: Other Financing(describe )
B32: Total Other Sources | E32: =SUM(E28:E31) -> 0
B34: Loan Financing | E34: =E25-E32 -> 0
B36: Total Sources | E36: =E32+E34 -> 0

Sheet Residential New
B1: SUMMARY
B3: Project DCR | C3: =IF(OR(('Residential New'!I113+'Non-Residential'!H79)=0, ISERR(('Residential New'!I113+'Non-Residential'!H79))), 0, ('Residential New'!I104+'Non-Residential'!H71)/('Residential New'!I113+'Non-Residential'!H79)) -> 0 | E3: Project LTC | G3: =IF('Project Budget'!E25=0, 0, ('Residential New'!I109+'Non-Residential'!H75)/'Project Budget'!E25) -> 0
B4: Residential DCR | C4: ='Residential New'!I114 -> 0 | E4: Residential LTC | G4: ='Residential New'!I119 -> 0
B5: Non-Residential DCR | C5: ='Non-Residential'!H80 -> 0 | E5: Non-Residential LTC | G5: ='Non-Residential'!H85 -> 0
B6: Minimum Affordability Met? | C6: ='Residential New'!L37 -> No | E6: Total Loan | G6: ='Residential New'!I109+'Non-Residential'!H75 -> 0
B7: Social Outcome Score | C7: =Scoring!H92 -> 0 | E7: Additional Equity Required | G7: ='Residential New'!I126+'Non-Residential'!H91 -> 0
B9: Lending Flexibility Score | C9: =Scoring!H130 -> 0 | E9: =Scoring!C155 -> Tier 3 - Up to 90% LTC, 45 yrs Am, 10 yr term
B13: Residential New: Financial Viability Assessment
B15: Percentage of Project Costs of Residential | D15: 1
B17: Is the Project Senior Independent Living? | D17: No
B19: 1. Project budget | F19: Per Unit | G19: New Rental
B20: Land market value | F20: =IF($D$60=0, "", G20/$D$60) | G20: =D$15*'Project Budget'!E17 -> 0
B21: Hard costs | F21: =IF($D$60=0, "", G21/$D$60) | G21: =D$15*'Project Budget'!E18 -> 0
B22: Soft costs | F22: =IF($D$60=0, "", G22/$D$60) | G22: =D$15*'Project Budget'!E19 -> 0
B23: Financing costs | F23: =IF($D$60=0, "", G23/$D$60) | G23: =D$15*'Project Budget'!E20 -> 0
B24: HST | F24: =IF($D$60=0, "", G24/$D$60) | G24: =D$15*'Project Budget'!E21 -> 0
B25: ='Project Budget'!B22 -> Misc and Buffer | F25: =IF($D$60=0, "", G25/$D$60) | G25: =D$15*'Project Budget'!E22 -> 0
B26: ='Project Budget'!B23 -> Other (describe) | F26: =IF($D$60=0, "", G26/$D$60) | G26: =D$15*'Project Budget'!E23 -> 0 | L26: Test 1
B27: ='Project Budget'!B24 -> Other (describe) | F27: =IF($D$60=0, "", G27/$D$60) | G27: =D$15*'Project Budget'!E24 -> 0 | L27: 20% of Units Affordable at 30% of Median Total Income
B28: Total Budget (Uses) | F28: =IF($D$60=0, "", G28/$D$60) | G28: =SUM(G20:G27) -> 0 | M28: Median Total Income CMA-StatCan *
L29: =L28*0.3 -> 0 | M29: 30% of Median Total Income
B30: Sources of Funding | L30: * Median total income, All Families
B31: Owner Cash Equity | F31: =IF($D$60=0, "", G31/$D$60) | G31: =I127 -> 0 | L31: https://www150.statcan.gc.ca/t1/tbl1/en/tv.action?pid=1110000901
B32: Land Value Equity | G32: =D$15*'Project Budget'!E29 -> 0 | L32: =ROUND(D60*0.2,0) -> 0 | M32: Min # units (rounded)
B33: ='Project Budget'!B30 -> Other Financing (describe ) | F33: =IF($D$60=0, "", G33/$D$60) | G33: =D$15*'Project Budget'!E30 -> 0 | L33: =ROUND(L29/12,0) -> 0 | M33: Max Rent for Test
B34: ='Project Budget'!B31 -> Other Financing(describe ) | F34: =IF($D$60=0, "", G34/$D$60) | G34: =D$15*'Project Budget'!E31 -> 0
B35: Total Other Sources | F35: =IF($D$60=0, "", I35/$D$60) | G35: =SUM(G31:G34) -> 0 | L35: =L60 -> 0 | M35: Units meeting Test
L36: =L61 -> 0 | M36: % Units that meet Test
L37: =IF(L35=0,"No",IF(L35>=L32, "Yes", "No")) -> No | M37: 20% Condition met?
E40: MONTHLY | G40: Proforma Rents | H40: Annual Potential Gross Income | I40: New Rental Annual Proforma | L40: Affordable units based on percentage of Median Total Income
B41: 2. Income Analysis- Residential | D41: Number | E41: Market | F41: Discounted Rent | K41: % | L41: 0.3 | M41: 0.25 | N41: 0.2 | O41: 0.15
B42: Unit type | C42: Size (sf) | D42: Units | E42: Rent(PGI) | F42: as % of Market | K42: Max Rent | L42: =L33 -> 0 | M42: =(($L$28*M41))/12 -> 0 | N42: =(($L$28*N41))/12 -> 0 | O42: =(($L$28*O41))/12 -> 0
B43: bachelor-market | G43: =E43 -> 0 | H43: =(E43*(D43+D44))*12 -> 0 | I43: =G43*D43*12 -> 0 | L43: =IF(G43<$L$33,D43,0) -> 0 | M43: =IF($G43<M$42,$D43,0) -> 0 | N43: =IF($G43<N$42,$D43,0) -> 0 | O43: =IF($G43<O$42,$D43,0) -> 0
B44: bachelor- discounted | G44: =E43*F44 -> 0 | I44: =G44*D44*12 -> 0 | L44: =IF(G44<$L$33,D44,0) -> 0 | M44: =IF($G44<M$42,$D44,0) -> 0 | N44: =IF($G44<N$42,$D44,0) -> 0 | O44: =IF($G44<O$42,$D44,0) -> 0
B45: 1 bed- market | G45: =E45 -> 0 | H45: =(E45*(D45+D46))*12 -> 0 | I45: =G45*D45*12 -> 0 | L45: =IF(G45<$L$33,D45,0) -> 0 | M45: =IF($G45<M$42,$D45,0) -> 0 | N45: =IF($G45<N$42,$D45,0) -> 0 | O45: =IF($G45<O$42,$D45,0) -> 0
B46: 1 bed- discounted | G46: =E45*F46 -> 0 | I46: =G46*D46*12 -> 0 | L46: =IF(G46<$L$33,D46,0) -> 0 | M46: =IF($G46<M$42,$D46,0) -> 0 | N46: =IF($G46<N$42,$D46,0) -> 0 | O46: =IF($G46<O$42,$D46,0) -> 0
B47: 1 bed+den- market | G47: =E47 -> 0 | H47: =(E47*(D47+D48))*12 -> 0 | I47: =G47*D47*12 -> 0 | L47: =IF(G47<$L$33,D47,0) -> 0 | M47: =IF($G47<M$42,$D47,0) -> 0 | N47: =IF($G47<N$42,$D47,0) -> 0 | O47: =IF($G47<O$42,$D47,0) -> 0
B48: 1 bed+den- discounted | G48: =E47*F48 -> 0 | I48: =G48*D48*12 -> 0 | L48: =IF(G48<$L$33,D48,0) -> 0 | M48: =IF($G48<M$42,$D48,0) -> 0 | N48: =IF($G48<N$42,$D48,0) -> 0 | O48: =IF($G48<O$42,$D48,0) -> 0
B49: 2 bed-market | G49: =E49 -> 0 | H49: =(E49*(D49+D50))*12 -> 0 | I49: =G49*D49*12 -> 0 | L49: =IF(G49<$L$33,D49,0) -> 0 | M49: =IF($G49<M$42,$D49,0) -> 0 | N49: =IF($G49<N$42,$D49,0) -> 0 | O49: =IF($G49<O$42,$D49,0) -> 0
B50: 2 bed - discounted | G50: =E49*F50 -> 0 | I50: =G50*D50*12 -> 0 | L50: =IF(G50<$L$33,D50,0) -> 0 | M50: =IF($G50<M$42,$D50,0) -> 0 | N50: =IF($G50<N$42,$D50,0) -> 0 | O50: =IF($G50<O$42,$D50,0) -> 0
...

Sheet Non-Residential
B1: SUMMARY
B3: Project DCR | C3: =IF(OR(('Residential New'!I113+'Non-Residential'!H79)=0, ISERR(('Residential New'!I113+'Non-Residential'!H79))), 0, ('Residential New'!I104+'Non-Residential'!H71)/('Residential New'!I113+'Non-Residential'!H79)) -> 0 | E3: Project LTC | H3: =IF('Project Budget'!E25=0, 0, ('Residential New'!I109+'Non-Residential'!H75)/'Project Budget'!E25) -> 0
B4: Residential DCR | C4: ='Residential New'!I114 -> 0 | E4: Residential LTC | H4: ='Residential New'!I119 -> 0
B5: Non-Residential DCR | C5: ='Non-Residential'!H80 -> 0 | E5: Non-Residential LTC | H5: ='Non-Residential'!H85 -> 0
B6: Minimum Affordability Met? | C6: ='Residential New'!L37 -> No | E6: Total Loan | H6: ='Residential New'!I109+'Non-Residential'!H75 -> 0
B7: Social Outcome Score | C7: =Scoring!H92 -> 0 | E7: Additional Equity Required | H7: ='Residential New'!I126+'Non-Residential'!H91 -> 0
B9: Lending Flexibility Score | C9: =Scoring!H130 -> 0 | E9: =Scoring!C155 -> Tier 3 - Up to 90% LTC, 45 yrs Am, 10 yr term
B13: Non-Residential : Financial Viability Assessment
E14: Test 1 | F14: (Non-Residential portion of project costs cannot exceed 30% of project costs)
B15: Percentage of Project Costs for Non-Residential | D15: 0 | E15: =IF(D15<=30%,"Yes","No") -> Yes | F15: Is the portion for non-residential costs under the limit?
E17: Test 2 | F17: Residential and Non-Residential must amount to 100% of project costs
E18: =IF(D15+'Residential New'!D15=100%,"Yes","No") -> Yes | F18: Does the total % amount to 100%?
E20: Test 3 | F20: Non-Residential portion of floor space cannot exceed 30% of project costs
B21: Percentage of Project Floor Space for Non-Residential | D21: =C50/(C50+'Residential New'!C60) -> #DIV/0! | E21: =IF(D21<=30%,"Yes","No") -> #DIV/0! | F21: Is the % of project floor space under the limit?
B23: 1. Project budget | C23: Non-Residential
B24: Land market value | C24: =D$15*'Project Budget'!E17 -> 0
B25: Hard costs | C25: =D$15*'Project Budget'!E18 -> 0
B26: Soft costs | C26: =D$15*'Project Budget'!E19 -> 0
B27: Financing costs | C27: =D$15*'Project Budget'!E20 -> 0
B28: HST | C28: =D$15*'Project Budget'!E21 -> 0
B29: ='Project Budget'!B22 -> Misc and Buffer | C29: =D$15*'Project Budget'!E22 -> 0
B30: ='Project Budget'!B23 -> Other (describe) | C30: =D$15*'Project Budget'!E23 -> 0
B31: ='Project Budget'!B24 -> Other (describe) | C31: =D$15*'Project Budget'!E24 -> 0
B32: Total Budget (Uses) | C32: =SUM(C24:C31) -> 0
B34: Other Sources of Funding
B35: Owner Cash Equity | C35: =H92 -> 0
B36: Land Value Equity | C36: ='Project Budget'!E29*'Non-Residential'!D15 -> 0
B37: ='Project Budget'!B30 -> Other Financing (describe ) | C37: ='Project Budget'!E30*'Non-Residential'!D15 -> 0
B38: ='Project Budget'!B31 -> Other Financing(describe ) | C38: ='Project Budget'!E31*'Non-Residential'!D15 -> 0
B39: Total Other Sources | C39: =SUM(C35:C38) -> 0
E43: MONTHLY | H43: ANNUAL
B44: 2. Non-Residential/Commercial | C44: Size (sf) | D44: # Units | E44: Rent
B45: Retail/Office 1 | H45: =D45*E45*12 -> 0
B46: Retail/Office 2 | H46: =D46*E46*12 -> 0
B47: Retail/Office 3 | H47: =D47*E47*12 -> 0
B48: Retail/Office 4 | H48: =D48*E48*12 -> 0
B49: Add: Recoveries
B50: Total | C50: =SUMPRODUCT(C45:C48,D45:D48) -> 0 | D50: =SUM(D45:D48) -> 0 | H50: =SUM(H45:H49) -> 0
B51: Vacancy rate /bad debt
B52: Less: Vacancy /bad debt | H52: =H51*H50 -> 0
...

Sheet Scoring
B1: SUMMARY | F1: SUMMARY
B3: Project DCR | D3: =IF(OR(('Residential New'!I113+'Non-Residential'!H79)=0, ISERR(('Residential New'!I113+'Non-Residential'!H79))), 0, ('Residential New'!I104+'Non-Residential'!H71)/('Residential New'!I113+'Non-Residential'!H79)) -> 0 | E3: Project LTC | G3: =IF('Project Budget'!E25=0, 0, ('Residential New'!I109+'Non-Residential'!H75)/'Project Budget'!E25) -> 0
B4: Residential DCR | D4: ='Residential New'!I114 -> 0 | E4: Residential LTC | G4: ='Residential New'!I119 -> 0
B5: Non-Residential DCR | D5: ='Non-Residential'!H80 -> 0 | E5: Non-Residential LTC | G5: ='Non-Residential'!H85 -> 0
B6: Minimum Affordability Met? | D6: ='Residential New'!L37 -> No | E6: Total Loan | G6: ='Residential New'!I109+'Non-Residential'!H75 -> 0
B7: Social Outcome Score | D7: =Scoring!H92 -> 0 | E7: Additional Equity Required | G7: ='Residential New'!I126+'Non-Residential'!H91 -> 0
B9: Lending Flexibility Score | D9: =Scoring!H130 -> 0 | E9: =Scoring!C155 -> Tier 3 - Up to 90% LTC, 45 yrs Am, 10 yr term
B13: Prioritization Scoring
E14: Option Set | G14: Answer | H14: Score
B15: Project location
D16: Please select if your property is located in an urban (within a CMA/CA) or rural area (outside CMA/CA). If rural, the Community Oriented category will not count towards your score, and your score will be normalized. | E16: Rural Urban | G16: Urban
B18: Affordability
D19: Is your application qualifying under Affordability Criteria A or B? | E19: Criteria A Criteria B | G19: Criteria A
D21: See the 'Affordability Score (Reference)' tab for scoring details.
B22: Affordability - duration | D22: 10 years and up to 14 years (Minimum Eligibility Requirement) | G22: 10 years and up to 14 years (Minimum Eligibility Requirement)
D23: 15 years and up to 19 years
D24: 20 years or more
B27: Affordability – depth* | D27: Rents at 30% of median income (Minimum Eligibility Requirement) | G27: Rents at 30% of median income (Minimum Eligibility Requirement) | H27: =IF(G27=D27,1, IF(G27=D28,2,IF(G27=D29,3,(IF(G27=D30,4,""))))) -> 1
D28: Rents at 25% of median income
D29: Rents at 20% of median income
D30: Rents at 15% of median income
D32: *All affordable units (depth) must meet the selected breadth.
B33: Affordability – breadth | D33: 20% of total units (Minimum Eligibility Requirement) | G33: 20% of total units (Minimum Eligibility Requirement) | H33: =IF(G33=D33,1,IF(G33=D34,2,IF(G33=D35,3,""))) -> 1
D34: 25% of total units
D35: 30% of total units
H36: {=IF(G22=D22, INDEX('Lending flex scorecard (hide)'!B20:E22, H33,H27), IF(G22=D23, INDEX('Lending flex scorecard (hide)'!B25:E27, H33,H27), IF(G22=D24, INDEX('Lending flex scorecard (hide)'!B30:E32, H33,H27),””)))} -> 0
B37: Affordability criteria score | D37: =IF(AND(G19="Criteria B",H36<11),"Under Criteria B, the affordability score will be the greater of 11 points or the calculated score above.","") | H37: =IF(G19="Criteria A",H36,IF(H36<11,11,H36)) -> 0
B39: Accessibility
D40: Project buildings with accessibility commitments must be 100% visitable and all common areas within the building must be barrier free.
D41: Project meets local accessibility standards as prescribed by the Municipality or Province/Territory. | E41: 0
D42: Min. 15% of the units are considered accessible in accordance with the CSA standard B651:23/B652:23 | E42: 5
D43: Min. 15% of units are universal design | E43: 5
B44: Level of accessibility | D44: The building receives Rick Hansen Foundation Accessibility Certification (60%-79% score) | E44: 5 | G44: 0 | H44: =G44 -> 0
D45: Min. 15% of units are considered accessible in accordance with the CSA standard B651:23/B652:23 and Min. 85% of units are universal design | E45: 10
D46: 100% of units are universal design | E46: 10
D47: 100% of units are accessible in accordance with the CSA standard B651:23/B652:23 | E47: 10
D48: The building receives Rick Hansen Foundation Accessibility Certification "Gold" (score of 80% or better) | E48: 10
B52: Adaptable units | D52: Project contains a minimum of 2 adaptable units, in addition to minimum 10% of unit accessible requirement. | E52: 2 | F52: 0= No 2= Yes | H52: =G52 -> 0
B54: Universal design units | D54: Project contains a minimum of 2 units with universal design, in addition to minimum 10% of unit accessible requirement. | E54: 2 | F54: 0= No 2= Yes | H54: =G54 -> 0
B56: Energy Efficiency - Greenhouse Gas
...

Sheet Scoring (Reference)
B2: Prioritization Grid - Affordability
B3: Affordability period of 10 years | C3: 30% median total income | D3: 25% median total income | E3: 20% median total income | F3: 15% median total income | H3: Criteria B | I3: Min Points
B4: 20% of Units | C4: 0 | D4: 5 | E4: 10 | F4: 16 | H4: Standard / Seniors Only | I4: 11
B5: 25% of Units | C5: 1 | D5: 7 | E5: 13 | F5: 20
B6: 30% of Units | C6: 2 | D6: 9 | E6: 16 | F6: 24
B8: Affordability period of 15 years | C8: 30% median total income | D8: 25% median total income | E8: 20% median total income | F8: 15% median total income
B9: 20% of Units | C9: 1 | D9: 7 | E9: 13 | F9: 20
B10: 25% of Units | C10: 2 | D10: 9 | E10: 16 | F10: 24
B11: 30% of Units | C11: 4 | D11: 12 | E11: 20 | F11: 29
B13: Affordability period of 20+ years | C13: 30% median total income | D13: 25% median total income | E13: 20% median total income | F13: 15% median total income
B14: 20% of Units | C14: 2 | D14: 9 | E14: 16 | F14: 23
B15: 25% of Units | C15: 4 | D15: 11 | E15: 20 | F15: 29
B16: 30% of Units | C16: 5 | D16: 13 | E16: 23 | F16: 36
B18: Lending Flexibility Scorecard- Affordability
B19: Affordability period of 10 years | C19: 30% median total income | D19: 25% median total income | E19: 20% median total income | F19: 15% median total income | H19: Criteria B | I19: Min Points
B20: 20% of Units | C20: 0 | D20: 8 | E20: 18 | F20: 30 | H20: Standard / Seniors Only | I20: 19
B21: 25% of Units | C21: 2 | D21: 12 | E21: 25 | F21: 40
B22: 30% of Units | C22: 4 | D22: 16 | E22: 31 | F22: 49
B24: Affordability period of 15 years | C24: 30% median total income | D24: 25% median total income | E24: 20% median total income | F24: 15% median total income
B25: 20% of Units | C25: 2 | D25: 11 | E25: 22 | F25: 36
B26: 25% of Units | C26: 4 | D26: 16 | E26: 30 | F26: 47
B27: 30% of Units | C27: 7 | D27: 20 | E27: 37 | F27: 57
B29: Affordability period of 20 years + | C29: 30% median total income | D29: 25% median total income | E29: 20% median total income | F29: 15% median total income
B30: 20% of Units | C30: 4 | D30: 14 | E30: 27 | F30: 42
B31: 25% of Units | C31: 7 | D31: 19 | E31: 35 | F31: 54
B32: 30% of Units | C32: 9 | D32: 24 | E32: 43 | F32: 65
B34: Scorecard - Energy Efficiency
B35: 2020 NECB Step Code (Part 3) | E35: Score
B36: Tier 1 - Baseline | E36: 0
B37: Tier 2 - 25% Improvement over Tier 1 | E37: 10
B38: Tier 3 - 50% Improvement over Tier 1 | E38: 20
B39: Tier 4 - 60% Improvement over Tier 1 | E39: 35
B40: 2020 NBC Step Code (Part 9) | E40: Score
B41: Tier 1 - Minimum Code | E41: 0
B42: Tier 2 - 10% more efficient | E42: 0
B43: Tier 3 - 20% more efficient | E43: 10
B44: Tier 4 - 40% more efficient | E44: 20
B45: Tier 5 - 70% more efficient | E45: 35

Sheet Lending flex scorecard (hide)
A2: Lending Flexibility Scorecard- Affordability
A3: Affordability period of 10 years | B3: 30% median total income | C3: 25% median total income | D3: 20% median total income | E3: 15% median total income
A4: 20% of Units | B4: 0 | C4: 8 | D4: 18 | E4: 30
A5: 25% of Units | B5: 2 | C5: 12 | D5: 25 | E5: 40
A6: 30% of Units | B6: 4 | C6: 16 | D6: 31 | E6: 49
A8: Affordability period of 15 years | B8: 30% median total income | C8: 25% median total income | D8: 20% median total income | E8: 15% median total income
A9: 20% of Units | B9: 2 | C9: 11 | D9: 22 | E9: 36
A10: 25% of Units | B10: 4 | C10: 16 | D10: 30 | E10: 47
A11: 30% of Units | B11: 7 | C11: 20 | D11: 37 | E11: 57
A13: Affordability period of 20+ years | B13: 30% median total income | C13: 25% median total income | D13: 20% median total income | E13: 15% median total income
A14: 20% of Units | B14: 4 | C14: 14 | D14: 27 | E14: 42
A15: 25% of Units | B15: 7 | C15: 19 | D15: 35 | E15: 54
A16: 30% of Units | B16: 9 | C16: 24 | D16: 43 | E16: 65
A18: Prioritization Grid - Affordability
A19: Affordability period of 10 years | B19: 30% median total income | C19: 25% median total income | D19: 20% median total income | E19: 15% median total income
A20: 20% of Units | B20: 0 | C20: 5 | D20: 10 | E20: 16
A21: 25% of Units | B21: 1 | C21: 7 | D21: 13 | E21: 20
A22: 30% of Units | B22: 2 | C22: 9 | D22: 16 | E22: 24
A24: Affordability period of 15 years | B24: 30% median total income | C24: 25% median total income | D24: 20% median total income | E24: 15% median total income
A25: 20% of Units | B25: 1 | C25: 7 | D25: 13 | E25: 20
A26: 25% of Units | B26: 2 | C26: 9 | D26: 16 | E26: 24
A27: 30% of Units | B27: 4 | C27: 12 | D27: 20 | E27: 29
A29: Affordability period of 20+ years | B29: 30% median total income | C29: 25% median total income | D29: 20% median total income | E29: 15% median total income
A30: 20% of Units | B30: 2 | C30: 9 | D30: 16 | E30: 23
A31: 25% of Units | B31: 4 | C31: 11 | D31: 20 | E31: 29
A32: 30% of Units | B32: 5 | C32: 13 | D32: 23 | E32: 36
A35: Criteria B | B35: Min Points
A36: Standard / Seniors Only | B36: 11
A38: Scorecard- Energy Efficiency
A39: 2020 NECB Step Code (Part 3) | B39: Score | D39: Scorecard- Market Adjusment
A40: Tier 1 - Baseline | B40: 0 | D40: Market Adjustment | E40: Score
A41: Tier 2 - 25% Improvement over Tier 1 | B41: 10 | D41: Market Type 1 | E41: 0
A42: Tier 3 - 50% Improvement over Tier 1 | B42: 20 | D42: Market Type 2 | E42: 9
A43: Tier 4 - 60% Improvement over Tier 1 | B43: 35 | D43: Market Type 3 | E43: 18
A44: 2020 NBC Step Code (Part 9) | B44: Score
A45: Tier 1 - Minimum Code | B45: 0
A46: Tier 2 - Minimum Code | B46: 0
A47: Tier 3 - Minimum Code | B47: 10
A48: Tier 4 - Minimum Code | B48: 20
A49: Tier 5 - Minimum Code | B49: 35

Sheet Market Adj. (hide)
A1: Geography | B1: Market | C1: Province
A2: Abbotsford-Mission, BC | B2: Market Type 3 | C2: British Columbia
A3: Alma, QC | B3: Market Type 1 | C3: Quebec
A4: Amos, QC | B4: Market Type 1 | C4: Quebec
A5: Baie-Comeau, QC | B5: Market Type 1 | C5: Quebec
A6: Barrie, ON | B6: Market Type 2 | C6: Ontario
A7: Bathurst, NB | B7: Market Type 1 | C7: New Brunswick
A8: Belleville-Quinte West, ON | B8: Market Type 2 | C8: Ontario
A9: Brandon, MB | B9: Market Type 1 | C9: Manitoba
A10: Brantford, ON | B10: Market Type 2 | C10: Ontario
A11: Brockville, ON | B11: Market Type 1 | C11: Ontario
A12: Brooks, AB | B12: Market Type 2 | C12: Alberta
... A168: Yorkton, SK | B168: Market Type 2 | C168: Saskatchewan

Sheet Mortg Calc
A1: Mortgage Calculator
C3: Principal | E3: 20000000 | G3: Total of All Payments: | H3: =E6*E7*E9 -> 3948787.9 | I3: over term
C4: Interest | E4: 0.025
C5: Comp Frequency | E5: 2 | F5: (2=Semi Annul, 4=Quarterly, 12=Monthly)
C6: Payment Freq | E6: 12 | F6: (Number of Payments a year)
C7: Term | E7: 5 | F7: (years)
C8: Amortization | E8: 40 | F8: (years)
C9: Calculated Pmt | E9: =(E3*(((1+E4/E5)^(E5/E6))-1)/((1-(1+E4/E5)^(-E8*E5)))) -> 65813.131 | F9: Overide: | G9: 0
C10: Interest Factor | E10: =((1+E4/E5)^(E5/E6))-1 -> 0.0020725648 | G10: (Use to override the Calulated Payment)
C11: Pmts Per Year | E11: =E9*12 -> 789757.58
